{
    "registryname": "alchemical_restructure_chamber",
    "localizedname":"placeholder",
    "activated_sound": "modularcontroller:machine_activated_science_fiction",
    "color": "535353",
    "parts": [
        {
            "x": -1,
            "y": 0,
            "z": 0,
            "elements": [
                "astralsorcery:blockmarble@3"
            ]
        },
        {
            "x": 4,
            "y": 8,
            "z": 4,
            "elements": "pipes_all"
        },
        {
            "x": -2,
            "y": 0,
            "z": 0,
            "elements": [
                "modularmachinery:blockinputbus",
                "modularmachinery:blockoutputbus",
                "modularmachinery:blockfluidoutputhatch"
            ]
        },
        {
            "x": 1,
            "y": 0,
            "z": 0,
            "elements": [
                "astralsorcery:blockmarble@3"
            ]
        },
        {
            "x": 5,
            "y": 8,
            "z": 4,
            "elements": [
                "chisel:glass@9"
            ]
        },
        {
            "x": -3,
            "y": 0,
            "z": 0,
            "elements": [
                "astralsorcery:blockmarble@3"
            ]
        },
        {
            "x": 2,
            "y": 0,
            "z": 0,
            "elements": [
                "modularmachinery:blockinputbus",
                "modularmachinery:blockoutputbus",
                "modularmachinery:blockfluidoutputhatch"
            ]
        },
        {
            "x": -4,
            "y": 0,
            "z": 0,
            "elements": [
                "contenttweaker:starlight_frame@0"
            ]
        },
        {
            "x": 3,
            "y": 0,
            "z": 0,
            "elements": [
                "astralsorcery:blockmarble@3"
            ]
        },
        {
            "x": -5,
            "y": 0,
            "z": 0,
            "elements": [
                "astralsorcery:blockmarble@4"
            ]
        },
        {
            "x": 4,
            "y": 0,
            "z": 0,
            "elements": [
                "contenttweaker:starlight_frame@0"
            ]
        },
        {
            "x": 5,
            "y": 0,
            "z": 0,
            "elements": [
                "astralsorcery:blockmarble@4"
            ]
        },
        {
            "x": -5,
            "y": 17,
            "z": 8,
            "elements": [
                "chisel:glass@9"
            ]
        },
        {
            "x": -4,
            "y": 17,
            "z": 8,
            "elements": "pipes_all"
        },
        {
            "x": -3,
            "y": 17,
            "z": 8,
            "elements": "pipes_all"
        },
        {
            "x": -2,
            "y": 17,
            "z": 8,
            "elements": "pipes_all"
        },
        {
            "x": -5,
            "y": 9,
            "z": 4,
            "elements": [
                "chisel:glass@9"
            ]
        },
        {
            "x": -1,
            "y": 17,
            "z": 8,
            "elements": "pipes_all"
        },
        {
            "x": -4,
            "y": 9,
            "z": 4,
            "elements": "pipes_all"
        },
        {
            "x": 0,
            "y": 17,
            "z": 8,
            "elements": "pipes_all"
        },
        {
            "x": -3,
            "y": 9,
            "z": 4,
            "elements": "pipes_all"
        },
        {
            "x": 1,
            "y": 17,
            "z": 8,
            "elements": "pipes_all"
        },
        {
            "x": -2,
            "y": 9,
            "z": 4,
            "elements": "pipes_all"
        },
        {
            "x": 2,
            "y": 17,
            "z": 8,
            "elements": "pipes_all"
        },
        {
            "x": -5,
            "y": 1,
            "z": 0,
            "elements": [
                "contenttweaker:starlight_frame@0"
            ]
        },
        {
            "x": -1,
            "y": 9,
            "z": 4,
            "elements": "pipes_all"
        },
        {
            "x": 3,
            "y": 17,
            "z": 8,
            "elements": "pipes_all"
        },
        {
            "x": -4,
            "y": 1,
            "z": 0,
            "elements": [
                "thaumcraft:stone_arcane@0"
            ]
        },
        {
            "x": 0,
            "y": 9,
            "z": 4,
            "elements": "pipes_all"
        },
        {
            "x": 4,
            "y": 17,
            "z": 8,
            "elements": "pipes_all"
        },
        {
            "x": -3,
            "y": 1,
            "z": 0,
            "elements": [
                "thaumcraft:stone_arcane@0"
            ]
        },
        {
            "x": 1,
            "y": 9,
            "z": 4,
            "elements": "pipes_all"
        },
        {
            "x": 5,
            "y": 17,
            "z": 8,
            "elements": [
                "chisel:glass@9"
            ]
        },
        {
            "x": -2,
            "y": 1,
            "z": 0,
            "elements": [
                "thaumcraft:stone_arcane@0"
            ]
        },
        {
            "x": 2,
            "y": 9,
            "z": 4,
            "elements": "pipes_all"
        },
        {
            "x": -1,
            "y": 1,
            "z": 0,
            "elements": [
                "thaumcraft:stone_arcane@0"
            ]
        },
        {
            "x": 3,
            "y": 9,
            "z": 4,
            "elements": "pipes_all"
        },
        {
            "x": 0,
            "y": 1,
            "z": 0,
            "elements": [
                "thaumcraft:stone_arcane@0"
            ]
        },
        {
            "x": 4,
            "y": 9,
            "z": 4,
            "elements": "pipes_all"
        },
        {
            "x": 1,
            "y": 1,
            "z": 0,
            "elements": [
                "thaumcraft:stone_arcane@0"
            ]
        },
        {
            "x": 5,
            "y": 9,
            "z": 4,
            "elements": [
                "chisel:glass@9"
            ]
        },
        {
            "x": 2,
            "y": 1,
            "z": 0,
            "elements": [
                "thaumcraft:stone_arcane@0"
            ]
        },
        {
            "x": 3,
            "y": 1,
            "z": 0,
            "elements": [
                "thaumcraft:stone_arcane@0"
            ]
        },
        {
            "x": 4,
            "y": 1,
            "z": 0,
            "elements": [
                "thaumcraft:stone_arcane@0"
            ]
        },
        {
            "x": 5,
            "y": 1,
            "z": 0,
            "elements": [
                "contenttweaker:starlight_frame@0"
            ]
        },
        {
            "x": -5,
            "y": 18,
            "z": 8,
            "elements": [
                "thaumcraft:stone_arcane@0"
            ]
        },
        {
            "x": -4,
            "y": 18,
            "z": 8,
            "elements": "pipes_all"
        },
        {
            "x": -3,
            "y": 18,
            "z": 8,
            "elements": "pipes_all"
        },
        {
            "x": -2,
            "y": 18,
            "z": 8,
            "elements": "pipes_all"
        },
        {
            "x": -5,
            "y": 10,
            "z": 4,
            "elements": [
                "chisel:glass@9"
            ]
        },
        {
            "x": -1,
            "y": 18,
            "z": 8,
            "elements": "pipes_all"
        },
        {
            "x": -4,
            "y": 10,
            "z": 4,
            "elements": "pipes_all"
        },
        {
            "x": 0,
            "y": 18,
            "z": 8,
            "elements": "pipes_all"
        },
        {
            "x": -3,
            "y": 10,
            "z": 4,
            "elements": "pipes_all"
        },
        {
            "x": 1,
            "y": 18,
            "z": 8,
            "elements": "pipes_all"
        },
        {
            "x": -2,
            "y": 10,
            "z": 4,
            "elements": "pipes_all"
        },
        {
            "x": 2,
            "y": 18,
            "z": 8,
            "elements": "pipes_all"
        },
        {
            "x": -5,
            "y": 2,
            "z": 0,
            "elements": [
                "astralsorcery:blockmarble@2"
            ]
        },
        {
            "x": -1,
            "y": 10,
            "z": 4,
            "elements": "pipes_all"
        },
        {
            "x": 3,
            "y": 18,
            "z": 8,
            "elements": "pipes_all"
        },
        {
            "x": -4,
            "y": 2,
            "z": 0,
            "elements": [
                "chisel:glass@9"
            ]
        },
        {
            "x": 0,
            "y": 10,
            "z": 4,
            "elements": "pipes_all"
        },
        {
            "x": 4,
            "y": 18,
            "z": 8,
            "elements": "pipes_all"
        },
        {
            "x": -3,
            "y": 2,
            "z": 0,
            "elements": [
                "chisel:glass@9"
            ]
        },
        {
            "x": 1,
            "y": 10,
            "z": 4,
            "elements": "pipes_all"
        },
        {
            "x": 5,
            "y": 18,
            "z": 8,
            "elements": [
                "thaumcraft:stone_arcane@0"
            ]
        },
        {
            "x": -2,
            "y": 2,
            "z": 0,
            "elements": [
                "chisel:glass@9"
            ]
        },
        {
            "x": 2,
            "y": 10,
            "z": 4,
            "elements": "pipes_all"
        },
        {
            "x": -1,
            "y": 2,
            "z": 0,
            "elements": [
                "chisel:glass@9"
            ]
        },
        {
            "x": 3,
            "y": 10,
            "z": 4,
            "elements": "pipes_all"
        },
        {
            "x": 0,
            "y": 2,
            "z": 0,
            "elements": [
                "chisel:glass@9"
            ]
        },
        {
            "x": 4,
            "y": 10,
            "z": 4,
            "elements": "pipes_all"
        },
        {
            "x": 1,
            "y": 2,
            "z": 0,
            "elements": [
                "chisel:glass@9"
            ]
        },
        {
            "x": 5,
            "y": 10,
            "z": 4,
            "elements": [
                "chisel:glass@9"
            ]
        },
        {
            "x": 2,
            "y": 2,
            "z": 0,
            "elements": [
                "chisel:glass@9"
            ]
        },
        {
            "x": 3,
            "y": 2,
            "z": 0,
            "elements": [
                "chisel:glass@9"
            ]
        },
        {
            "x": 4,
            "y": 2,
            "z": 0,
            "elements": [
                "chisel:glass@9"
            ]
        },
        {
            "x": 5,
            "y": 2,
            "z": 0,
            "elements": [
                "astralsorcery:blockmarble@2"
            ]
        },
        {
            "x": -5,
            "y": 19,
            "z": 8,
            "elements": [
                "astralsorcery:blockmarble@3"
            ]
        },
        {
            "x": -4,
            "y": 19,
            "z": 8,
            "elements": [
                "thaumicaugmentation:fortified_glass@0"
            ]
        },
        {
            "x": -3,
            "y": 19,
            "z": 8,
            "elements": [
                "thaumicaugmentation:fortified_glass@0"
            ]
        },
        {
            "x": -2,
            "y": 19,
            "z": 8,
            "elements": [
                "thaumicaugmentation:fortified_glass@0"
            ]
        },
        {
            "x": -5,
            "y": 11,
            "z": 4,
            "elements": [
                "chisel:glass@9"
            ]
        },
        {
            "x": -1,
            "y": 19,
            "z": 8,
            "elements": [
                "thaumicaugmentation:fortified_glass@0"
            ]
        },
        {
            "x": -4,
            "y": 11,
            "z": 4,
            "elements": "pipes_all"
        },
        {
            "x": 0,
            "y": 19,
            "z": 8,
            "elements": [
                "thaumicaugmentation:fortified_glass@0"
            ]
        },
        {
            "x": -3,
            "y": 11,
            "z": 4,
            "elements": "pipes_all"
        },
        {
            "x": 1,
            "y": 19,
            "z": 8,
            "elements": [
                "thaumicaugmentation:fortified_glass@0"
            ]
        },
        {
            "x": -2,
            "y": 11,
            "z": 4,
            "elements": "pipes_all"
        },
        {
            "x": 2,
            "y": 19,
            "z": 8,
            "elements": [
                "thaumicaugmentation:fortified_glass@0"
            ]
        },
        {
            "x": -5,
            "y": 3,
            "z": 0,
            "elements": [
                "astralsorcery:blockmarble@2"
            ]
        },
        {
            "x": -1,
            "y": 11,
            "z": 4,
            "elements": "pipes_all"
        },
        {
            "x": 3,
            "y": 19,
            "z": 8,
            "elements": [
                "thaumicaugmentation:fortified_glass@0"
            ]
        },
        {
            "x": -4,
            "y": 3,
            "z": 0,
            "elements": [
                "chisel:glass@9"
            ]
        },
        {
            "x": 0,
            "y": 11,
            "z": 4,
            "elements": "pipes_all"
        },
        {
            "x": 4,
            "y": 19,
            "z": 8,
            "elements": [
                "thaumicaugmentation:fortified_glass@0"
            ]
        },
        {
            "x": -3,
            "y": 3,
            "z": 0,
            "elements": [
                "chisel:glass@9"
            ]
        },
        {
            "x": 1,
            "y": 11,
            "z": 4,
            "elements": "pipes_all"
        },
        {
            "x": 5,
            "y": 19,
            "z": 8,
            "elements": [
                "astralsorcery:blockmarble@3"
            ]
        },
        {
            "x": -2,
            "y": 3,
            "z": 0,
            "elements": [
                "chisel:glass@9"
            ]
        },
        {
            "x": 2,
            "y": 11,
            "z": 4,
            "elements": "pipes_all"
        },
        {
            "x": -1,
            "y": 3,
            "z": 0,
            "elements": [
                "chisel:glass@9"
            ]
        },
        {
            "x": 3,
            "y": 11,
            "z": 4,
            "elements": "pipes_all"
        },
        {
            "x": 0,
            "y": 3,
            "z": 0,
            "elements": [
                "chisel:glass@9"
            ]
        },
        {
            "x": 4,
            "y": 11,
            "z": 4,
            "elements": "pipes_all"
        },
        {
            "x": 1,
            "y": 3,
            "z": 0,
            "elements": [
                "chisel:glass@9"
            ]
        },
        {
            "x": 5,
            "y": 11,
            "z": 4,
            "elements": [
                "chisel:glass@9"
            ]
        },
        {
            "x": 2,
            "y": 3,
            "z": 0,
            "elements": [
                "chisel:glass@9"
            ]
        },
        {
            "x": 3,
            "y": 3,
            "z": 0,
            "elements": [
                "chisel:glass@9"
            ]
        },
        {
            "x": 4,
            "y": 3,
            "z": 0,
            "elements": [
                "chisel:glass@9"
            ]
        },
        {
            "x": 5,
            "y": 3,
            "z": 0,
            "elements": [
                "astralsorcery:blockmarble@2"
            ]
        },
        {
            "x": -5,
            "y": 12,
            "z": 4,
            "elements": [
                "chisel:glass@9"
            ]
        },
        {
            "x": -4,
            "y": 12,
            "z": 4,
            "elements": "pipes_all"
        },
        {
            "x": -3,
            "y": 12,
            "z": 4,
            "elements": "pipes_all"
        },
        {
            "x": -2,
            "y": 12,
            "z": 4,
            "elements": "pipes_all"
        },
        {
            "x": -5,
            "y": 4,
            "z": 0,
            "elements": [
                "astralsorcery:blockmarble@2"
            ]
        },
        {
            "x": -1,
            "y": 12,
            "z": 4,
            "elements": "pipes_all"
        },
        {
            "x": -4,
            "y": 4,
            "z": 0,
            "elements": [
                "chisel:glass@9"
            ]
        },
        {
            "x": 0,
            "y": 12,
            "z": 4,
            "elements": "pipes_all"
        },
        {
            "x": -3,
            "y": 4,
            "z": 0,
            "elements": [
                "chisel:glass@9"
            ]
        },
        {
            "x": 1,
            "y": 12,
            "z": 4,
            "elements": "pipes_all"
        },
        {
            "x": -2,
            "y": 4,
            "z": 0,
            "elements": [
                "chisel:glass@9"
            ]
        },
        {
            "x": 2,
            "y": 12,
            "z": 4,
            "elements": "pipes_all"
        },
        {
            "x": -1,
            "y": 4,
            "z": 0,
            "elements": [
                "chisel:glass@9"
            ]
        },
        {
            "x": 3,
            "y": 12,
            "z": 4,
            "elements": "pipes_all"
        },
        {
            "x": 0,
            "y": 4,
            "z": 0,
            "elements": [
                "chisel:glass@9"
            ]
        },
        {
            "x": 4,
            "y": 12,
            "z": 4,
            "elements": "pipes_all"
        },
        {
            "x": 1,
            "y": 4,
            "z": 0,
            "elements": [
                "chisel:glass@9"
            ]
        },
        {
            "x": 5,
            "y": 12,
            "z": 4,
            "elements": [
                "chisel:glass@9"
            ]
        },
        {
            "x": 2,
            "y": 4,
            "z": 0,
            "elements": [
                "chisel:glass@9"
            ]
        },
        {
            "x": 3,
            "y": 4,
            "z": 0,
            "elements": [
                "chisel:glass@9"
            ]
        },
        {
            "x": 4,
            "y": 4,
            "z": 0,
            "elements": [
                "chisel:glass@9"
            ]
        },
        {
            "x": 5,
            "y": 4,
            "z": 0,
            "elements": [
                "astralsorcery:blockmarble@2"
            ]
        },
        {
            "x": -5,
            "y": 13,
            "z": 4,
            "elements": [
                "chisel:glass@9"
            ]
        },
        {
            "x": -4,
            "y": 13,
            "z": 4,
            "elements": "pipes_all"
        },
        {
            "x": -3,
            "y": 13,
            "z": 4,
            "elements": "pipes_all"
        },
        {
            "x": -2,
            "y": 13,
            "z": 4,
            "elements": "pipes_all"
        },
        {
            "x": -5,
            "y": 5,
            "z": 0,
            "elements": [
                "astralsorcery:blockmarble@2"
            ]
        },
        {
            "x": -1,
            "y": 13,
            "z": 4,
            "elements": "pipes_all"
        },
        {
            "x": -4,
            "y": 5,
            "z": 0,
            "elements": [
                "chisel:glass@9"
            ]
        },
        {
            "x": 0,
            "y": 13,
            "z": 4,
            "elements": "pipes_all"
        },
        {
            "x": -3,
            "y": 5,
            "z": 0,
            "elements": [
                "chisel:glass@9"
            ]
        },
        {
            "x": 1,
            "y": 13,
            "z": 4,
            "elements": "pipes_all"
        },
        {
            "x": -2,
            "y": 5,
            "z": 0,
            "elements": [
                "chisel:glass@9"
            ]
        },
        {
            "x": 2,
            "y": 13,
            "z": 4,
            "elements": "pipes_all"
        },
        {
            "x": -1,
            "y": 5,
            "z": 0,
            "elements": [
                "chisel:glass@9"
            ]
        },
        {
            "x": 3,
            "y": 13,
            "z": 4,
            "elements": "pipes_all"
        },
        {
            "x": 0,
            "y": 5,
            "z": 0,
            "elements": [
                "chisel:glass@9"
            ]
        },
        {
            "x": 4,
            "y": 13,
            "z": 4,
            "elements": "pipes_all"
        },
        {
            "x": 1,
            "y": 5,
            "z": 0,
            "elements": [
                "chisel:glass@9"
            ]
        },
        {
            "x": 5,
            "y": 13,
            "z": 4,
            "elements": [
                "chisel:glass@9"
            ]
        },
        {
            "x": 2,
            "y": 5,
            "z": 0,
            "elements": [
                "chisel:glass@9"
            ]
        },
        {
            "x": 3,
            "y": 5,
            "z": 0,
            "elements": [
                "chisel:glass@9"
            ]
        },
        {
            "x": 4,
            "y": 5,
            "z": 0,
            "elements": [
                "chisel:glass@9"
            ]
        },
        {
            "x": 5,
            "y": 5,
            "z": 0,
            "elements": [
                "astralsorcery:blockmarble@2"
            ]
        },
        {
            "x": -5,
            "y": 14,
            "z": 4,
            "elements": [
                "chisel:glass@9"
            ]
        },
        {
            "x": -4,
            "y": 14,
            "z": 4,
            "elements": "pipes_all"
        },
        {
            "x": -3,
            "y": 14,
            "z": 4,
            "elements": "pipes_all"
        },
        {
            "x": -2,
            "y": 14,
            "z": 4,
            "elements": "pipes_all"
        },
        {
            "x": -5,
            "y": 6,
            "z": 0,
            "elements": [
                "astralsorcery:blockmarble@2"
            ]
        },
        {
            "x": -1,
            "y": 14,
            "z": 4,
            "elements": "pipes_all"
        },
        {
            "x": -4,
            "y": 6,
            "z": 0,
            "elements": [
                "chisel:glass@9"
            ]
        },
        {
            "x": 0,
            "y": 14,
            "z": 4,
            "elements": "pipes_all"
        },
        {
            "x": -3,
            "y": 6,
            "z": 0,
            "elements": [
                "chisel:glass@9"
            ]
        },
        {
            "x": 1,
            "y": 14,
            "z": 4,
            "elements": "pipes_all"
        },
        {
            "x": -2,
            "y": 6,
            "z": 0,
            "elements": [
                "chisel:glass@9"
            ]
        },
        {
            "x": 2,
            "y": 14,
            "z": 4,
            "elements": "pipes_all"
        },
        {
            "x": -1,
            "y": 6,
            "z": 0,
            "elements": [
                "chisel:glass@9"
            ]
        },
        {
            "x": 3,
            "y": 14,
            "z": 4,
            "elements": "pipes_all"
        },
        {
            "x": 0,
            "y": 6,
            "z": 0,
            "elements": [
                "chisel:glass@9"
            ]
        },
        {
            "x": 4,
            "y": 14,
            "z": 4,
            "elements": "pipes_all"
        },
        {
            "x": 1,
            "y": 6,
            "z": 0,
            "elements": [
                "chisel:glass@9"
            ]
        },
        {
            "x": 5,
            "y": 14,
            "z": 4,
            "elements": [
                "chisel:glass@9"
            ]
        },
        {
            "x": 2,
            "y": 6,
            "z": 0,
            "elements": [
                "chisel:glass@9"
            ]
        },
        {
            "x": 3,
            "y": 6,
            "z": 0,
            "elements": [
                "chisel:glass@9"
            ]
        },
        {
            "x": 4,
            "y": 6,
            "z": 0,
            "elements": [
                "chisel:glass@9"
            ]
        },
        {
            "x": 5,
            "y": 6,
            "z": 0,
            "elements": [
                "astralsorcery:blockmarble@2"
            ]
        },
        {
            "x": -5,
            "y": 15,
            "z": 4,
            "elements": [
                "chisel:glass@9"
            ]
        },
        {
            "x": -4,
            "y": 15,
            "z": 4,
            "elements": "pipes_all"
        },
        {
            "x": -3,
            "y": 15,
            "z": 4,
            "elements": "pipes_all"
        },
        {
            "x": -2,
            "y": 15,
            "z": 4,
            "elements": "pipes_all"
        },
        {
            "x": -5,
            "y": 7,
            "z": 0,
            "elements": [
                "astralsorcery:blockmarble@2"
            ]
        },
        {
            "x": -1,
            "y": 15,
            "z": 4,
            "elements": "pipes_all"
        },
        {
            "x": -4,
            "y": 7,
            "z": 0,
            "elements": [
                "chisel:glass@9"
            ]
        },
        {
            "x": 0,
            "y": 15,
            "z": 4,
            "elements": "pipes_all"
        },
        {
            "x": -3,
            "y": 7,
            "z": 0,
            "elements": [
                "chisel:glass@9"
            ]
        },
        {
            "x": 1,
            "y": 15,
            "z": 4,
            "elements": "pipes_all"
        },
        {
            "x": -2,
            "y": 7,
            "z": 0,
            "elements": [
                "chisel:glass@9"
            ]
        },
        {
            "x": 2,
            "y": 15,
            "z": 4,
            "elements": "pipes_all"
        },
        {
            "x": -1,
            "y": 7,
            "z": 0,
            "elements": [
                "chisel:glass@9"
            ]
        },
        {
            "x": 3,
            "y": 15,
            "z": 4,
            "elements": "pipes_all"
        },
        {
            "x": 0,
            "y": 7,
            "z": 0,
            "elements": [
                "chisel:glass@9"
            ]
        },
        {
            "x": 4,
            "y": 15,
            "z": 4,
            "elements": "pipes_all"
        },
        {
            "x": 1,
            "y": 7,
            "z": 0,
            "elements": [
                "chisel:glass@9"
            ]
        },
        {
            "x": 5,
            "y": 15,
            "z": 4,
            "elements": [
                "chisel:glass@9"
            ]
        },
        {
            "x": 2,
            "y": 7,
            "z": 0,
            "elements": [
                "chisel:glass@9"
            ]
        },
        {
            "x": 3,
            "y": 7,
            "z": 0,
            "elements": [
                "chisel:glass@9"
            ]
        },
        {
            "x": 4,
            "y": 7,
            "z": 0,
            "elements": [
                "chisel:glass@9"
            ]
        },
        {
            "x": 5,
            "y": 7,
            "z": 0,
            "elements": [
                "astralsorcery:blockmarble@2"
            ]
        },
        {
            "x": -5,
            "y": 16,
            "z": 4,
            "elements": [
                "chisel:glass@9"
            ]
        },
        {
            "x": -4,
            "y": 16,
            "z": 4,
            "elements": "pipes_all"
        },
        {
            "x": -3,
            "y": 16,
            "z": 4,
            "elements": "pipes_all"
        },
        {
            "x": -2,
            "y": 16,
            "z": 4,
            "elements": "pipes_all"
        },
        {
            "x": -5,
            "y": 8,
            "z": 0,
            "elements": [
                "astralsorcery:blockmarble@2"
            ]
        },
        {
            "x": -1,
            "y": 16,
            "z": 4,
            "elements": "pipes_all"
        },
        {
            "x": -4,
            "y": 8,
            "z": 0,
            "elements": [
                "chisel:glass@9"
            ]
        },
        {
            "x": 0,
            "y": 16,
            "z": 4,
            "elements": "pipes_all"
        },
        {
            "x": -3,
            "y": 8,
            "z": 0,
            "elements": [
                "chisel:glass@9"
            ]
        },
        {
            "x": 1,
            "y": 16,
            "z": 4,
            "elements": "pipes_all"
        },
        {
            "x": -2,
            "y": 8,
            "z": 0,
            "elements": [
                "chisel:glass@9"
            ]
        },
        {
            "x": 2,
            "y": 16,
            "z": 4,
            "elements": "pipes_all"
        },
        {
            "x": -1,
            "y": 8,
            "z": 0,
            "elements": [
                "chisel:glass@9"
            ]
        },
        {
            "x": 3,
            "y": 16,
            "z": 4,
            "elements": "pipes_all"
        },
        {
            "x": 0,
            "y": 8,
            "z": 0,
            "elements": [
                "chisel:glass@9"
            ]
        },
        {
            "x": 4,
            "y": 16,
            "z": 4,
            "elements": "pipes_all"
        },
        {
            "x": 1,
            "y": 8,
            "z": 0,
            "elements": [
                "chisel:glass@9"
            ]
        },
        {
            "x": 5,
            "y": 16,
            "z": 4,
            "elements": [
                "chisel:glass@9"
            ]
        },
        {
            "x": 2,
            "y": 8,
            "z": 0,
            "elements": [
                "chisel:glass@9"
            ]
        },
        {
            "x": 3,
            "y": 8,
            "z": 0,
            "elements": [
                "chisel:glass@9"
            ]
        },
        {
            "x": 4,
            "y": 8,
            "z": 0,
            "elements": [
                "chisel:glass@9"
            ]
        },
        {
            "x": 5,
            "y": 8,
            "z": 0,
            "elements": [
                "astralsorcery:blockmarble@2"
            ]
        },
        {
            "x": -5,
            "y": 17,
            "z": 4,
            "elements": [
                "chisel:glass@9"
            ]
        },
        {
            "x": -4,
            "y": 17,
            "z": 4,
            "elements": "pipes_all"
        },
        {
            "x": -3,
            "y": 17,
            "z": 4,
            "elements": "pipes_all"
        },
        {
            "x": -2,
            "y": 17,
            "z": 4,
            "elements": "pipes_all"
        },
        {
            "x": -5,
            "y": 9,
            "z": 0,
            "elements": [
                "astralsorcery:blockmarble@2"
            ]
        },
        {
            "x": -1,
            "y": 17,
            "z": 4,
            "elements": "pipes_all"
        },
        {
            "x": -4,
            "y": 9,
            "z": 0,
            "elements": [
                "chisel:glass@9"
            ]
        },
        {
            "x": 0,
            "y": 17,
            "z": 4,
            "elements": "pipes_all"
        },
        {
            "x": -3,
            "y": 9,
            "z": 0,
            "elements": [
                "chisel:glass@9"
            ]
        },
        {
            "x": 1,
            "y": 17,
            "z": 4,
            "elements": "pipes_all"
        },
        {
            "x": -2,
            "y": 9,
            "z": 0,
            "elements": [
                "chisel:glass@9"
            ]
        },
        {
            "x": 2,
            "y": 17,
            "z": 4,
            "elements": "pipes_all"
        },
        {
            "x": -1,
            "y": 9,
            "z": 0,
            "elements": [
                "chisel:glass@9"
            ]
        },
        {
            "x": 3,
            "y": 17,
            "z": 4,
            "elements": "pipes_all"
        },
        {
            "x": 0,
            "y": 9,
            "z": 0,
            "elements": [
                "chisel:glass@9"
            ]
        },
        {
            "x": 4,
            "y": 17,
            "z": 4,
            "elements": "pipes_all"
        },
        {
            "x": 1,
            "y": 9,
            "z": 0,
            "elements": [
                "chisel:glass@9"
            ]
        },
        {
            "x": 5,
            "y": 17,
            "z": 4,
            "elements": [
                "chisel:glass@9"
            ]
        },
        {
            "x": 2,
            "y": 9,
            "z": 0,
            "elements": [
                "chisel:glass@9"
            ]
        },
        {
            "x": 3,
            "y": 9,
            "z": 0,
            "elements": [
                "chisel:glass@9"
            ]
        },
        {
            "x": 4,
            "y": 9,
            "z": 0,
            "elements": [
                "chisel:glass@9"
            ]
        },
        {
            "x": 5,
            "y": 9,
            "z": 0,
            "elements": [
                "astralsorcery:blockmarble@2"
            ]
        },
        {
            "x": -5,
            "y": 18,
            "z": 4,
            "elements": [
                "thaumcraft:stone_arcane@0"
            ]
        },
        {
            "x": -4,
            "y": 18,
            "z": 4,
            "elements": "pipes_all"
        },
        {
            "x": -3,
            "y": 18,
            "z": 4,
            "elements": "pipes_all"
        },
        {
            "x": -2,
            "y": 18,
            "z": 4,
            "elements": "pipes_all"
        },
        {
            "x": -5,
            "y": 10,
            "z": 0,
            "elements": [
                "astralsorcery:blockmarble@2"
            ]
        },
        {
            "x": -1,
            "y": 18,
            "z": 4,
            "elements": "pipes_all"
        },
        {
            "x": -4,
            "y": 10,
            "z": 0,
            "elements": [
                "chisel:glass@9"
            ]
        },
        {
            "x": 0,
            "y": 18,
            "z": 4,
            "elements": "pipes_all"
        },
        {
            "x": -3,
            "y": 10,
            "z": 0,
            "elements": [
                "chisel:glass@9"
            ]
        },
        {
            "x": 1,
            "y": 18,
            "z": 4,
            "elements": "pipes_all"
        },
        {
            "x": -2,
            "y": 10,
            "z": 0,
            "elements": [
                "chisel:glass@9"
            ]
        },
        {
            "x": 2,
            "y": 18,
            "z": 4,
            "elements": "pipes_all"
        },
        {
            "x": -1,
            "y": 10,
            "z": 0,
            "elements": [
                "chisel:glass@9"
            ]
        },
        {
            "x": 3,
            "y": 18,
            "z": 4,
            "elements": "pipes_all"
        },
        {
            "x": 0,
            "y": 10,
            "z": 0,
            "elements": [
                "chisel:glass@9"
            ]
        },
        {
            "x": 4,
            "y": 18,
            "z": 4,
            "elements": "pipes_all"
        },
        {
            "x": 1,
            "y": 10,
            "z": 0,
            "elements": [
                "chisel:glass@9"
            ]
        },
        {
            "x": 5,
            "y": 18,
            "z": 4,
            "elements": [
                "thaumcraft:stone_arcane@0"
            ]
        },
        {
            "x": 2,
            "y": 10,
            "z": 0,
            "elements": [
                "chisel:glass@9"
            ]
        },
        {
            "x": 3,
            "y": 10,
            "z": 0,
            "elements": [
                "chisel:glass@9"
            ]
        },
        {
            "x": 4,
            "y": 10,
            "z": 0,
            "elements": [
                "chisel:glass@9"
            ]
        },
        {
            "x": 5,
            "y": 10,
            "z": 0,
            "elements": [
                "astralsorcery:blockmarble@2"
            ]
        },
        {
            "x": -5,
            "y": 19,
            "z": 4,
            "elements": [
                "astralsorcery:blockmarble@3"
            ]
        },
        {
            "x": -4,
            "y": 19,
            "z": 4,
            "elements": [
                "thaumicaugmentation:fortified_glass@0"
            ]
        },
        {
            "x": -3,
            "y": 19,
            "z": 4,
            "elements": [
                "thaumicaugmentation:fortified_glass@0"
            ]
        },
        {
            "x": -2,
            "y": 19,
            "z": 4,
            "elements": [
                "hdsutils:alchemy_input_hatch@0"
            ]
        },
        {
            "x": -5,
            "y": 11,
            "z": 0,
            "elements": [
                "astralsorcery:blockmarble@2"
            ]
        },
        {
            "x": -1,
            "y": 19,
            "z": 4,
            "elements": [
                "thaumicaugmentation:fortified_glass@0"
            ]
        },
        {
            "x": -4,
            "y": 11,
            "z": 0,
            "elements": [
                "chisel:glass@9"
            ]
        },
        {
            "x": 0,
            "y": 19,
            "z": 4,
            "elements": [
                "thaumicaugmentation:fortified_glass@0"
            ]
        },
        {
            "x": -3,
            "y": 11,
            "z": 0,
            "elements": [
                "chisel:glass@9"
            ]
        },
        {
            "x": 1,
            "y": 19,
            "z": 4,
            "elements": [
                "thaumicaugmentation:fortified_glass@0"
            ]
        },
        {
            "x": -2,
            "y": 11,
            "z": 0,
            "elements": [
                "chisel:glass@9"
            ]
        },
        {
            "x": 2,
            "y": 19,
            "z": 4,
            "elements": [
                "hdsutils:alchemy_input_hatch@0"
            ]
        },
        {
            "x": -1,
            "y": 11,
            "z": 0,
            "elements": [
                "chisel:glass@9"
            ]
        },
        {
            "x": 3,
            "y": 19,
            "z": 4,
            "elements": [
                "thaumicaugmentation:fortified_glass@0"
            ]
        },
        {
            "x": 0,
            "y": 11,
            "z": 0,
            "elements": [
                "chisel:glass@9"
            ]
        },
        {
            "x": 4,
            "y": 19,
            "z": 4,
            "elements": [
                "thaumicaugmentation:fortified_glass@0"
            ]
        },
        {
            "x": 1,
            "y": 11,
            "z": 0,
            "elements": [
                "chisel:glass@9"
            ]
        },
        {
            "x": 5,
            "y": 19,
            "z": 4,
            "elements": [
                "astralsorcery:blockmarble@3"
            ]
        },
        {
            "x": 2,
            "y": 11,
            "z": 0,
            "elements": [
                "chisel:glass@9"
            ]
        },
        {
            "x": 3,
            "y": 11,
            "z": 0,
            "elements": [
                "chisel:glass@9"
            ]
        },
        {
            "x": 4,
            "y": 11,
            "z": 0,
            "elements": [
                "chisel:glass@9"
            ]
        },
        {
            "x": 5,
            "y": 11,
            "z": 0,
            "elements": [
                "astralsorcery:blockmarble@2"
            ]
        },
        {
            "x": -5,
            "y": 12,
            "z": 0,
            "elements": [
                "astralsorcery:blockmarble@2"
            ]
        },
        {
            "x": -4,
            "y": 12,
            "z": 0,
            "elements": [
                "chisel:glass@9"
            ]
        },
        {
            "x": -3,
            "y": 12,
            "z": 0,
            "elements": [
                "chisel:glass@9"
            ]
        },
        {
            "x": -2,
            "y": 12,
            "z": 0,
            "elements": [
                "chisel:glass@9"
            ]
        },
        {
            "x": -1,
            "y": 12,
            "z": 0,
            "elements": [
                "chisel:glass@9"
            ]
        },
        {
            "x": 0,
            "y": 12,
            "z": 0,
            "elements": [
                "chisel:glass@9"
            ]
        },
        {
            "x": 1,
            "y": 12,
            "z": 0,
            "elements": [
                "chisel:glass@9"
            ]
        },
        {
            "x": 2,
            "y": 12,
            "z": 0,
            "elements": [
                "chisel:glass@9"
            ]
        },
        {
            "x": 3,
            "y": 12,
            "z": 0,
            "elements": [
                "chisel:glass@9"
            ]
        },
        {
            "x": 4,
            "y": 12,
            "z": 0,
            "elements": [
                "chisel:glass@9"
            ]
        },
        {
            "x": 5,
            "y": 12,
            "z": 0,
            "elements": [
                "astralsorcery:blockmarble@2"
            ]
        },
        {
            "x": -5,
            "y": 13,
            "z": 0,
            "elements": [
                "astralsorcery:blockmarble@2"
            ]
        },
        {
            "x": -4,
            "y": 13,
            "z": 0,
            "elements": [
                "chisel:glass@9"
            ]
        },
        {
            "x": -3,
            "y": 13,
            "z": 0,
            "elements": [
                "chisel:glass@9"
            ]
        },
        {
            "x": -2,
            "y": 13,
            "z": 0,
            "elements": [
                "chisel:glass@9"
            ]
        },
        {
            "x": -1,
            "y": 13,
            "z": 0,
            "elements": [
                "chisel:glass@9"
            ]
        },
        {
            "x": 0,
            "y": 13,
            "z": 0,
            "elements": [
                "chisel:glass@9"
            ]
        },
        {
            "x": 1,
            "y": 13,
            "z": 0,
            "elements": [
                "chisel:glass@9"
            ]
        },
        {
            "x": 2,
            "y": 13,
            "z": 0,
            "elements": [
                "chisel:glass@9"
            ]
        },
        {
            "x": 3,
            "y": 13,
            "z": 0,
            "elements": [
                "chisel:glass@9"
            ]
        },
        {
            "x": 4,
            "y": 13,
            "z": 0,
            "elements": [
                "chisel:glass@9"
            ]
        },
        {
            "x": 5,
            "y": 13,
            "z": 0,
            "elements": [
                "astralsorcery:blockmarble@2"
            ]
        },
        {
            "x": -5,
            "y": 14,
            "z": 0,
            "elements": [
                "astralsorcery:blockmarble@2"
            ]
        },
        {
            "x": -4,
            "y": 14,
            "z": 0,
            "elements": [
                "chisel:glass@9"
            ]
        },
        {
            "x": -3,
            "y": 14,
            "z": 0,
            "elements": [
                "chisel:glass@9"
            ]
        },
        {
            "x": -2,
            "y": 14,
            "z": 0,
            "elements": [
                "chisel:glass@9"
            ]
        },
        {
            "x": -1,
            "y": 14,
            "z": 0,
            "elements": [
                "chisel:glass@9"
            ]
        },
        {
            "x": 0,
            "y": 14,
            "z": 0,
            "elements": [
                "chisel:glass@9"
            ]
        },
        {
            "x": 1,
            "y": 14,
            "z": 0,
            "elements": [
                "chisel:glass@9"
            ]
        },
        {
            "x": 2,
            "y": 14,
            "z": 0,
            "elements": [
                "chisel:glass@9"
            ]
        },
        {
            "x": 3,
            "y": 14,
            "z": 0,
            "elements": [
                "chisel:glass@9"
            ]
        },
        {
            "x": 4,
            "y": 14,
            "z": 0,
            "elements": [
                "chisel:glass@9"
            ]
        },
        {
            "x": 5,
            "y": 14,
            "z": 0,
            "elements": [
                "astralsorcery:blockmarble@2"
            ]
        },
        {
            "x": -5,
            "y": 0,
            "z": 9,
            "elements": [
                "contenttweaker:starlight_frame@0"
            ]
        },
        {
            "x": -4,
            "y": 0,
            "z": 9,
            "elements": [
                "thaumicaugmentation:fortified_glass@0"
            ]
        },
        {
            "x": -3,
            "y": 0,
            "z": 9,
            "elements": [
                "thaumicaugmentation:fortified_glass@0"
            ]
        },
        {
            "x": -2,
            "y": 0,
            "z": 9,
            "elements": [
                "thaumicaugmentation:fortified_glass@0"
            ]
        },
        {
            "x": -1,
            "y": 0,
            "z": 9,
            "elements": [
                "thaumicaugmentation:fortified_glass@0"
            ]
        },
        {
            "x": 0,
            "y": 0,
            "z": 9,
            "elements": [
                "thaumicaugmentation:fortified_glass@0"
            ]
        },
        {
            "x": 1,
            "y": 0,
            "z": 9,
            "elements": [
                "thaumicaugmentation:fortified_glass@0"
            ]
        },
        {
            "x": 2,
            "y": 0,
            "z": 9,
            "elements": [
                "thaumicaugmentation:fortified_glass@0"
            ]
        },
        {
            "x": -5,
            "y": 15,
            "z": 0,
            "elements": [
                "astralsorcery:blockmarble@2"
            ]
        },
        {
            "x": 3,
            "y": 0,
            "z": 9,
            "elements": [
                "thaumicaugmentation:fortified_glass@0"
            ]
        },
        {
            "x": -4,
            "y": 15,
            "z": 0,
            "elements": [
                "chisel:glass@9"
            ]
        },
        {
            "x": 4,
            "y": 0,
            "z": 9,
            "elements": [
                "thaumicaugmentation:fortified_glass@0"
            ]
        },
        {
            "x": -3,
            "y": 15,
            "z": 0,
            "elements": [
                "chisel:glass@9"
            ]
        },
        {
            "x": 5,
            "y": 0,
            "z": 9,
            "elements": [
                "contenttweaker:starlight_frame@0"
            ]
        },
        {
            "x": -2,
            "y": 15,
            "z": 0,
            "elements": [
                "chisel:glass@9"
            ]
        },
        {
            "x": -1,
            "y": 15,
            "z": 0,
            "elements": [
                "chisel:glass@9"
            ]
        },
        {
            "x": 0,
            "y": 15,
            "z": 0,
            "elements": [
                "chisel:glass@9"
            ]
        },
        {
            "x": 1,
            "y": 15,
            "z": 0,
            "elements": [
                "chisel:glass@9"
            ]
        },
        {
            "x": 2,
            "y": 15,
            "z": 0,
            "elements": [
                "chisel:glass@9"
            ]
        },
        {
            "x": 3,
            "y": 15,
            "z": 0,
            "elements": [
                "chisel:glass@9"
            ]
        },
        {
            "x": 4,
            "y": 15,
            "z": 0,
            "elements": [
                "chisel:glass@9"
            ]
        },
        {
            "x": 5,
            "y": 15,
            "z": 0,
            "elements": [
                "astralsorcery:blockmarble@2"
            ]
        },
        {
            "x": -5,
            "y": 1,
            "z": 9,
            "elements": [
                "thaumcraft:stone_arcane@0"
            ]
        },
        {
            "x": -4,
            "y": 1,
            "z": 9,
            "elements": [
                "astralsorcery:blockmarble@1"
            ]
        },
        {
            "x": -3,
            "y": 1,
            "z": 9,
            "elements": [
                "astralsorcery:blockmarble@3"
            ]
        },
        {
            "x": -2,
            "y": 1,
            "z": 9,
            "elements": [
                "astralsorcery:blockmarble@1"
            ]
        },
        {
            "x": -1,
            "y": 1,
            "z": 9,
            "elements": [
                "astralsorcery:blockmarble@3"
            ]
        },
        {
            "x": 0,
            "y": 1,
            "z": 9,
            "elements": [
                "astralsorcery:blockmarble@3"
            ]
        },
        {
            "x": 1,
            "y": 1,
            "z": 9,
            "elements": [
                "astralsorcery:blockmarble@3"
            ]
        },
        {
            "x": 2,
            "y": 1,
            "z": 9,
            "elements": [
                "astralsorcery:blockmarble@3"
            ]
        },
        {
            "x": -5,
            "y": 16,
            "z": 0,
            "elements": [
                "astralsorcery:blockmarble@2"
            ]
        },
        {
            "x": 3,
            "y": 1,
            "z": 9,
            "elements": [
                "astralsorcery:blockmarble@4"
            ]
        },
        {
            "x": -4,
            "y": 16,
            "z": 0,
            "elements": [
                "chisel:glass@9"
            ]
        },
        {
            "x": 4,
            "y": 1,
            "z": 9,
            "elements": [
                "modularmachinery:blockfluidinputhatch@1"
            ]
        },
        {
            "x": -3,
            "y": 16,
            "z": 0,
            "elements": [
                "chisel:glass@9"
            ]
        },
        {
            "x": 5,
            "y": 1,
            "z": 9,
            "elements": [
                "thaumcraft:stone_arcane@0"
            ]
        },
        {
            "x": -2,
            "y": 16,
            "z": 0,
            "elements": [
                "chisel:glass@9"
            ]
        },
        {
            "x": -1,
            "y": 16,
            "z": 0,
            "elements": [
                "chisel:glass@9"
            ]
        },
        {
            "x": 0,
            "y": 16,
            "z": 0,
            "elements": [
                "chisel:glass@9"
            ]
        },
        {
            "x": 1,
            "y": 16,
            "z": 0,
            "elements": [
                "chisel:glass@9"
            ]
        },
        {
            "x": 2,
            "y": 16,
            "z": 0,
            "elements": [
                "chisel:glass@9"
            ]
        },
        {
            "x": 3,
            "y": 16,
            "z": 0,
            "elements": [
                "chisel:glass@9"
            ]
        },
        {
            "x": 4,
            "y": 16,
            "z": 0,
            "elements": [
                "chisel:glass@9"
            ]
        },
        {
            "x": 5,
            "y": 16,
            "z": 0,
            "elements": [
                "astralsorcery:blockmarble@2"
            ]
        },
        {
            "x": -5,
            "y": 2,
            "z": 9,
            "elements": [
                "chisel:glass@9"
            ]
        },
        {
            "x": -4,
            "y": 2,
            "z": 9,
            "elements": "pipes_all"
        },
        {
            "x": -3,
            "y": 2,
            "z": 9,
            "elements": "pipes_all"
        },
        {
            "x": -2,
            "y": 2,
            "z": 9,
            "elements": "pipes_all"
        },
        {
            "x": -1,
            "y": 2,
            "z": 9,
            "elements": "pipes_all"
        },
        {
            "x": 0,
            "y": 2,
            "z": 9,
            "elements": "pipes_all"
        },
        {
            "x": 1,
            "y": 2,
            "z": 9,
            "elements": "pipes_all"
        },
        {
            "x": 2,
            "y": 2,
            "z": 9,
            "elements": "pipes_all"
        },
        {
            "x": -5,
            "y": 17,
            "z": 0,
            "elements": [
                "astralsorcery:blockmarble@2"
            ]
        },
        {
            "x": 3,
            "y": 2,
            "z": 9,
            "elements": "pipes_all"
        },
        {
            "x": -4,
            "y": 17,
            "z": 0,
            "elements": [
                "chisel:glass@9"
            ]
        },
        {
            "x": 4,
            "y": 2,
            "z": 9,
            "elements": [
                "hdsutils:alchemy_output_hatch@2"
            ]
        },
        {
            "x": -3,
            "y": 17,
            "z": 0,
            "elements": [
                "chisel:glass@9"
            ]
        },
        {
            "x": 5,
            "y": 2,
            "z": 9,
            "elements": [
                "chisel:glass@9"
            ]
        },
        {
            "x": -2,
            "y": 17,
            "z": 0,
            "elements": [
                "chisel:glass@9"
            ]
        },
        {
            "x": -1,
            "y": 17,
            "z": 0,
            "elements": [
                "chisel:glass@9"
            ]
        },
        {
            "x": 0,
            "y": 17,
            "z": 0,
            "elements": [
                "chisel:glass@9"
            ]
        },
        {
            "x": 1,
            "y": 17,
            "z": 0,
            "elements": [
                "chisel:glass@9"
            ]
        },
        {
            "x": 2,
            "y": 17,
            "z": 0,
            "elements": [
                "chisel:glass@9"
            ]
        },
        {
            "x": 3,
            "y": 17,
            "z": 0,
            "elements": [
                "chisel:glass@9"
            ]
        },
        {
            "x": 4,
            "y": 17,
            "z": 0,
            "elements": [
                "chisel:glass@9"
            ]
        },
        {
            "x": 5,
            "y": 17,
            "z": 0,
            "elements": [
                "astralsorcery:blockmarble@2"
            ]
        },
        {
            "x": -5,
            "y": 3,
            "z": 9,
            "elements": [
                "chisel:glass@9"
            ]
        },
        {
            "x": -4,
            "y": 3,
            "z": 9,
            "elements": "pipes_all"
        },
        {
            "x": -3,
            "y": 3,
            "z": 9,
            "elements": "pipes_all"
        },
        {
            "x": -2,
            "y": 3,
            "z": 9,
            "elements": "pipes_all"
        },
        {
            "x": -1,
            "y": 3,
            "z": 9,
            "elements": "pipes_all"
        },
        {
            "x": 0,
            "y": 3,
            "z": 9,
            "elements": "pipes_all"
        },
        {
            "x": 1,
            "y": 3,
            "z": 9,
            "elements": "pipes_all"
        },
        {
            "x": 2,
            "y": 3,
            "z": 9,
            "elements": "pipes_all"
        },
        {
            "x": -5,
            "y": 18,
            "z": 0,
            "elements": [
                "contenttweaker:starlight_frame@0"
            ]
        },
        {
            "x": 3,
            "y": 3,
            "z": 9,
            "elements": "pipes_all"
        },
        {
            "x": -4,
            "y": 18,
            "z": 0,
            "elements": [
                "thaumcraft:stone_arcane@0"
            ]
        },
        {
            "x": 4,
            "y": 3,
            "z": 9,
            "elements": "pipes_all"
        },
        {
            "x": -3,
            "y": 18,
            "z": 0,
            "elements": [
                "thaumcraft:stone_arcane@0"
            ]
        },
        {
            "x": 5,
            "y": 3,
            "z": 9,
            "elements": [
                "chisel:glass@9"
            ]
        },
        {
            "x": -2,
            "y": 18,
            "z": 0,
            "elements": [
                "thaumcraft:stone_arcane@0"
            ]
        },
        {
            "x": -1,
            "y": 18,
            "z": 0,
            "elements": [
                "thaumcraft:stone_arcane@0"
            ]
        },
        {
            "x": 0,
            "y": 18,
            "z": 0,
            "elements": [
                "thaumcraft:stone_arcane@0"
            ]
        },
        {
            "x": 1,
            "y": 18,
            "z": 0,
            "elements": [
                "thaumcraft:stone_arcane@0"
            ]
        },
        {
            "x": 2,
            "y": 18,
            "z": 0,
            "elements": [
                "thaumcraft:stone_arcane@0"
            ]
        },
        {
            "x": 3,
            "y": 18,
            "z": 0,
            "elements": [
                "thaumcraft:stone_arcane@0"
            ]
        },
        {
            "x": 4,
            "y": 18,
            "z": 0,
            "elements": [
                "thaumcraft:stone_arcane@0"
            ]
        },
        {
            "x": 5,
            "y": 18,
            "z": 0,
            "elements": [
                "contenttweaker:starlight_frame@0"
            ]
        },
        {
            "x": -5,
            "y": 4,
            "z": 9,
            "elements": [
                "chisel:glass@9"
            ]
        },
        {
            "x": -4,
            "y": 4,
            "z": 9,
            "elements": "pipes_all"
        },
        {
            "x": -3,
            "y": 4,
            "z": 9,
            "elements": "pipes_all"
        },
        {
            "x": -2,
            "y": 4,
            "z": 9,
            "elements": "pipes_all"
        },
        {
            "x": -1,
            "y": 4,
            "z": 9,
            "elements": "pipes_all"
        },
        {
            "x": 0,
            "y": 4,
            "z": 9,
            "elements": "pipes_all"
        },
        {
            "x": 1,
            "y": 4,
            "z": 9,
            "elements": "pipes_all"
        },
        {
            "x": 2,
            "y": 4,
            "z": 9,
            "elements": "pipes_all"
        },
        {
            "x": -5,
            "y": 19,
            "z": 0,
            "elements": [
                "astralsorcery:blockmarble@4"
            ]
        },
        {
            "x": 3,
            "y": 4,
            "z": 9,
            "elements": "pipes_all"
        },
        {
            "x": -4,
            "y": 19,
            "z": 0,
            "elements": [
                "contenttweaker:starlight_frame@0"
            ]
        },
        {
            "x": 4,
            "y": 4,
            "z": 9,
            "elements": "pipes_all"
        },
        {
            "x": -3,
            "y": 19,
            "z": 0,
            "elements": [
                "astralsorcery:blockmarble@3"
            ]
        },
        {
            "x": 5,
            "y": 4,
            "z": 9,
            "elements": [
                "chisel:glass@9"
            ]
        },
        {
            "x": -2,
            "y": 19,
            "z": 0,
            "elements": [
                "astralsorcery:blockmarble@3"
            ]
        },
        {
            "x": -1,
            "y": 19,
            "z": 0,
            "elements": [
                "astralsorcery:blockmarble@3"
            ]
        },
        {
            "x": 0,
            "y": 19,
            "z": 0,
            "elements": [
                "astralsorcery:blockmarble@3"
            ]
        },
        {
            "x": 1,
            "y": 19,
            "z": 0,
            "elements": [
                "astralsorcery:blockmarble@3"
            ]
        },
        {
            "x": 2,
            "y": 19,
            "z": 0,
            "elements": [
                "astralsorcery:blockmarble@3"
            ]
        },
        {
            "x": 3,
            "y": 19,
            "z": 0,
            "elements": [
                "astralsorcery:blockmarble@3"
            ]
        },
        {
            "x": 4,
            "y": 19,
            "z": 0,
            "elements": [
                "contenttweaker:starlight_frame@0"
            ]
        },
        {
            "x": 5,
            "y": 19,
            "z": 0,
            "elements": [
                "astralsorcery:blockmarble@4"
            ]
        },
        {
            "x": -5,
            "y": 5,
            "z": 9,
            "elements": [
                "chisel:glass@9"
            ]
        },
        {
            "x": -4,
            "y": 5,
            "z": 9,
            "elements": "pipes_all"
        },
        {
            "x": -3,
            "y": 5,
            "z": 9,
            "elements": "pipes_all"
        },
        {
            "x": -2,
            "y": 5,
            "z": 9,
            "elements": "pipes_all"
        },
        {
            "x": -1,
            "y": 5,
            "z": 9,
            "elements": "pipes_all"
        },
        {
            "x": 0,
            "y": 5,
            "z": 9,
            "elements": "pipes_all"
        },
        {
            "x": 1,
            "y": 5,
            "z": 9,
            "elements": "pipes_all"
        },
        {
            "x": 2,
            "y": 5,
            "z": 9,
            "elements": "pipes_all"
        },
        {
            "x": 3,
            "y": 5,
            "z": 9,
            "elements": "pipes_all"
        },
        {
            "x": 4,
            "y": 5,
            "z": 9,
            "elements": "pipes_all"
        },
        {
            "x": 5,
            "y": 5,
            "z": 9,
            "elements": [
                "chisel:glass@9"
            ]
        },
        {
            "x": -5,
            "y": 6,
            "z": 9,
            "elements": [
                "chisel:glass@9"
            ]
        },
        {
            "x": -4,
            "y": 6,
            "z": 9,
            "elements": "pipes_all"
        },
        {
            "x": -3,
            "y": 6,
            "z": 9,
            "elements": "pipes_all"
        },
        {
            "x": -2,
            "y": 6,
            "z": 9,
            "elements": "pipes_all"
        },
        {
            "x": -1,
            "y": 6,
            "z": 9,
            "elements": "pipes_all"
        },
        {
            "x": 0,
            "y": 6,
            "z": 9,
            "elements": "pipes_all"
        },
        {
            "x": 1,
            "y": 6,
            "z": 9,
            "elements": "pipes_all"
        },
        {
            "x": 2,
            "y": 6,
            "z": 9,
            "elements": "pipes_all"
        },
        {
            "x": 3,
            "y": 6,
            "z": 9,
            "elements": "pipes_all"
        },
        {
            "x": 4,
            "y": 6,
            "z": 9,
            "elements": "pipes_all"
        },
        {
            "x": 5,
            "y": 6,
            "z": 9,
            "elements": [
                "chisel:glass@9"
            ]
        },
        {
            "x": -5,
            "y": 7,
            "z": 9,
            "elements": [
                "chisel:glass@9"
            ]
        },
        {
            "x": -4,
            "y": 7,
            "z": 9,
            "elements": "pipes_all"
        },
        {
            "x": -3,
            "y": 7,
            "z": 9,
            "elements": "pipes_all"
        },
        {
            "x": -2,
            "y": 7,
            "z": 9,
            "elements": "pipes_all"
        },
        {
            "x": -1,
            "y": 7,
            "z": 9,
            "elements": "pipes_all"
        },
        {
            "x": 0,
            "y": 7,
            "z": 9,
            "elements": "pipes_all"
        },
        {
            "x": 1,
            "y": 7,
            "z": 9,
            "elements": "pipes_all"
        },
        {
            "x": 2,
            "y": 7,
            "z": 9,
            "elements": "pipes_all"
        },
        {
            "x": 3,
            "y": 7,
            "z": 9,
            "elements": "pipes_all"
        },
        {
            "x": 4,
            "y": 7,
            "z": 9,
            "elements": "pipes_all"
        },
        {
            "x": 5,
            "y": 7,
            "z": 9,
            "elements": [
                "chisel:glass@9"
            ]
        },
        {
            "x": -5,
            "y": 8,
            "z": 9,
            "elements": [
                "chisel:glass@9"
            ]
        },
        {
            "x": -4,
            "y": 8,
            "z": 9,
            "elements": "pipes_all"
        },
        {
            "x": -3,
            "y": 8,
            "z": 9,
            "elements": "pipes_all"
        },
        {
            "x": -2,
            "y": 8,
            "z": 9,
            "elements": "pipes_all"
        },
        {
            "x": -5,
            "y": 0,
            "z": 5,
            "elements": [
                "astralsorcery:blockmarble@3"
            ]
        },
        {
            "x": -1,
            "y": 8,
            "z": 9,
            "elements": "pipes_all"
        },
        {
            "x": -4,
            "y": 0,
            "z": 5,
            "elements": [
                "thaumicaugmentation:fortified_glass@0"
            ]
        },
        {
            "x": 0,
            "y": 8,
            "z": 9,
            "elements": "pipes_all"
        },
        {
            "x": -3,
            "y": 0,
            "z": 5,
            "elements": [
                "thaumicaugmentation:fortified_glass@0"
            ]
        },
        {
            "x": 1,
            "y": 8,
            "z": 9,
            "elements": "pipes_all"
        },
        {
            "x": -2,
            "y": 0,
            "z": 5,
            "elements": [
                "thaumicaugmentation:fortified_glass@0"
            ]
        },
        {
            "x": 2,
            "y": 8,
            "z": 9,
            "elements": "pipes_all"
        },
        {
            "x": -1,
            "y": 0,
            "z": 5,
            "elements": [
                "thaumicaugmentation:fortified_glass@0"
            ]
        },
        {
            "x": 3,
            "y": 8,
            "z": 9,
            "elements": "pipes_all"
        },
        {
            "x": 0,
            "y": 0,
            "z": 5,
            "elements": [
                "thaumicaugmentation:fortified_glass@0"
            ]
        },
        {
            "x": 4,
            "y": 8,
            "z": 9,
            "elements": "pipes_all"
        },
        {
            "x": 1,
            "y": 0,
            "z": 5,
            "elements": [
                "thaumicaugmentation:fortified_glass@0"
            ]
        },
        {
            "x": 5,
            "y": 8,
            "z": 9,
            "elements": [
                "chisel:glass@9"
            ]
        },
        {
            "x": 2,
            "y": 0,
            "z": 5,
            "elements": [
                "thaumicaugmentation:fortified_glass@0"
            ]
        },
        {
            "x": 3,
            "y": 0,
            "z": 5,
            "elements": [
                "thaumicaugmentation:fortified_glass@0"
            ]
        },
        {
            "x": 4,
            "y": 0,
            "z": 5,
            "elements": [
                "thaumicaugmentation:fortified_glass@0"
            ]
        },
        {
            "x": 5,
            "y": 0,
            "z": 5,
            "elements": [
                "astralsorcery:blockmarble@3"
            ]
        },
        {
            "x": -5,
            "y": 9,
            "z": 9,
            "elements": [
                "chisel:glass@9"
            ]
        },
        {
            "x": -4,
            "y": 9,
            "z": 9,
            "elements": "pipes_all"
        },
        {
            "x": -3,
            "y": 9,
            "z": 9,
            "elements": "pipes_all"
        },
        {
            "x": -2,
            "y": 9,
            "z": 9,
            "elements": "pipes_all"
        },
        {
            "x": -5,
            "y": 1,
            "z": 5,
            "elements": [
                "thaumcraft:stone_arcane@0"
            ]
        },
        {
            "x": -1,
            "y": 9,
            "z": 9,
            "elements": "pipes_all"
        },
        {
            "x": -4,
            "y": 1,
            "z": 5,
            "elements": [
                "astralsorcery:blockmarble@1"
            ]
        },
        {
            "x": 0,
            "y": 9,
            "z": 9,
            "elements": "pipes_all"
        },
        {
            "x": -3,
            "y": 1,
            "z": 5,
            "elements": [
                "astralsorcery:blockmarble@3"
            ]
        },
        {
            "x": 1,
            "y": 9,
            "z": 9,
            "elements": "pipes_all"
        },
        {
            "x": -2,
            "y": 1,
            "z": 5,
            "elements": [
                "astralsorcery:blockmarble@6"
            ]
        },
        {
            "x": 2,
            "y": 9,
            "z": 9,
            "elements": "pipes_all"
        },
        {
            "x": -1,
            "y": 1,
            "z": 5,
            "elements": [
                "astralsorcery:blockmarble@4"
            ]
        },
        {
            "x": 3,
            "y": 9,
            "z": 9,
            "elements": "pipes_all"
        },
        {
            "x": 0,
            "y": 1,
            "z": 5,
            "elements": [
                "astralsorcery:blockmarble@6"
            ]
        },
        {
            "x": 4,
            "y": 9,
            "z": 9,
            "elements": "pipes_all"
        },
        {
            "x": 1,
            "y": 1,
            "z": 5,
            "elements": [
                "astralsorcery:blockmarble@1"
            ]
        },
        {
            "x": 5,
            "y": 9,
            "z": 9,
            "elements": [
                "chisel:glass@9"
            ]
        },
        {
            "x": 2,
            "y": 1,
            "z": 5,
            "elements": [
                "astralsorcery:blockmarble@3"
            ]
        },
        {
            "x": 3,
            "y": 1,
            "z": 5,
            "elements": [
                "astralsorcery:blockmarble@1"
            ]
        },
        {
            "x": 4,
            "y": 1,
            "z": 5,
            "elements": [
                "astralsorcery:blockmarble@3"
            ]
        },
        {
            "x": 5,
            "y": 1,
            "z": 5,
            "elements": [
                "thaumcraft:stone_arcane@0"
            ]
        },
        {
            "x": -5,
            "y": 10,
            "z": 9,
            "elements": [
                "chisel:glass@9"
            ]
        },
        {
            "x": -4,
            "y": 10,
            "z": 9,
            "elements": "pipes_all"
        },
        {
            "x": -3,
            "y": 10,
            "z": 9,
            "elements": "pipes_all"
        },
        {
            "x": -2,
            "y": 10,
            "z": 9,
            "elements": "pipes_all"
        },
        {
            "x": -5,
            "y": 2,
            "z": 5,
            "elements": [
                "chisel:glass@9"
            ]
        },
        {
            "x": -1,
            "y": 10,
            "z": 9,
            "elements": "pipes_all"
        },
        {
            "x": -4,
            "y": 2,
            "z": 5,
            "elements": "pipes_all"
        },
        {
            "x": 0,
            "y": 10,
            "z": 9,
            "elements": "pipes_all"
        },
        {
            "x": -3,
            "y": 2,
            "z": 5,
            "elements": "pipes_all"
        },
        {
            "x": 1,
            "y": 10,
            "z": 9,
            "elements": "pipes_all"
        },
        {
            "x": -2,
            "y": 2,
            "z": 5,
            "elements": "pipes_all"
        },
        {
            "x": 2,
            "y": 10,
            "z": 9,
            "elements": "pipes_all"
        },
        {
            "x": -1,
            "y": 2,
            "z": 5,
            "elements": "pipes_all"
        },
        {
            "x": 3,
            "y": 10,
            "z": 9,
            "elements": "pipes_all"
        },
        {
            "x": 0,
            "y": 2,
            "z": 5,
            "elements": "pipes_all"
        },
        {
            "x": 4,
            "y": 10,
            "z": 9,
            "elements": "pipes_all"
        },
        {
            "x": 1,
            "y": 2,
            "z": 5,
            "elements": "pipes_all"
        },
        {
            "x": 5,
            "y": 10,
            "z": 9,
            "elements": [
                "chisel:glass@9"
            ]
        },
        {
            "x": 2,
            "y": 2,
            "z": 5,
            "elements": "pipes_all"
        },
        {
            "x": 3,
            "y": 2,
            "z": 5,
            "elements": "pipes_all"
        },
        {
            "x": 4,
            "y": 2,
            "z": 5,
            "elements": "pipes_all"
        },
        {
            "x": 5,
            "y": 2,
            "z": 5,
            "elements": [
                "chisel:glass@9"
            ]
        },
        {
            "x": -5,
            "y": 11,
            "z": 9,
            "elements": [
                "chisel:glass@9"
            ]
        },
        {
            "x": -4,
            "y": 11,
            "z": 9,
            "elements": "pipes_all"
        },
        {
            "x": -3,
            "y": 11,
            "z": 9,
            "elements": "pipes_all"
        },
        {
            "x": -2,
            "y": 11,
            "z": 9,
            "elements": "pipes_all"
        },
        {
            "x": -5,
            "y": 3,
            "z": 5,
            "elements": [
                "chisel:glass@9"
            ]
        },
        {
            "x": -1,
            "y": 11,
            "z": 9,
            "elements": "pipes_all"
        },
        {
            "x": -4,
            "y": 3,
            "z": 5,
            "elements": "pipes_all"
        },
        {
            "x": 0,
            "y": 11,
            "z": 9,
            "elements": "pipes_all"
        },
        {
            "x": -3,
            "y": 3,
            "z": 5,
            "elements": "pipes_all"
        },
        {
            "x": 1,
            "y": 11,
            "z": 9,
            "elements": "pipes_all"
        },
        {
            "x": -2,
            "y": 3,
            "z": 5,
            "elements": "pipes_all"
        },
        {
            "x": 2,
            "y": 11,
            "z": 9,
            "elements": "pipes_all"
        },
        {
            "x": -1,
            "y": 3,
            "z": 5,
            "elements": "pipes_all"
        },
        {
            "x": 3,
            "y": 11,
            "z": 9,
            "elements": "pipes_all"
        },
        {
            "x": 0,
            "y": 3,
            "z": 5,
            "elements": "pipes_all"
        },
        {
            "x": 4,
            "y": 11,
            "z": 9,
            "elements": "pipes_all"
        },
        {
            "x": 1,
            "y": 3,
            "z": 5,
            "elements": "pipes_all"
        },
        {
            "x": 5,
            "y": 11,
            "z": 9,
            "elements": [
                "chisel:glass@9"
            ]
        },
        {
            "x": 2,
            "y": 3,
            "z": 5,
            "elements": "pipes_all"
        },
        {
            "x": 3,
            "y": 3,
            "z": 5,
            "elements": "pipes_all"
        },
        {
            "x": 4,
            "y": 3,
            "z": 5,
            "elements": "pipes_all"
        },
        {
            "x": 5,
            "y": 3,
            "z": 5,
            "elements": [
                "chisel:glass@9"
            ]
        },
        {
            "x": -5,
            "y": 12,
            "z": 9,
            "elements": [
                "chisel:glass@9"
            ]
        },
        {
            "x": -4,
            "y": 12,
            "z": 9,
            "elements": "pipes_all"
        },
        {
            "x": -3,
            "y": 12,
            "z": 9,
            "elements": "pipes_all"
        },
        {
            "x": -2,
            "y": 12,
            "z": 9,
            "elements": "pipes_all"
        },
        {
            "x": -5,
            "y": 4,
            "z": 5,
            "elements": [
                "chisel:glass@9"
            ]
        },
        {
            "x": -1,
            "y": 12,
            "z": 9,
            "elements": "pipes_all"
        },
        {
            "x": -4,
            "y": 4,
            "z": 5,
            "elements": "pipes_all"
        },
        {
            "x": 0,
            "y": 12,
            "z": 9,
            "elements": "pipes_all"
        },
        {
            "x": -3,
            "y": 4,
            "z": 5,
            "elements": "pipes_all"
        },
        {
            "x": 1,
            "y": 12,
            "z": 9,
            "elements": "pipes_all"
        },
        {
            "x": -2,
            "y": 4,
            "z": 5,
            "elements": "pipes_all"
        },
        {
            "x": 2,
            "y": 12,
            "z": 9,
            "elements": "pipes_all"
        },
        {
            "x": -1,
            "y": 4,
            "z": 5,
            "elements": "pipes_all"
        },
        {
            "x": 3,
            "y": 12,
            "z": 9,
            "elements": "pipes_all"
        },
        {
            "x": 0,
            "y": 4,
            "z": 5,
            "elements": "pipes_all"
        },
        {
            "x": 4,
            "y": 12,
            "z": 9,
            "elements": "pipes_all"
        },
        {
            "x": 1,
            "y": 4,
            "z": 5,
            "elements": "pipes_all"
        },
        {
            "x": 5,
            "y": 12,
            "z": 9,
            "elements": [
                "chisel:glass@9"
            ]
        },
        {
            "x": 2,
            "y": 4,
            "z": 5,
            "elements": "pipes_all"
        },
        {
            "x": 3,
            "y": 4,
            "z": 5,
            "elements": "pipes_all"
        },
        {
            "x": 4,
            "y": 4,
            "z": 5,
            "elements": "pipes_all"
        },
        {
            "x": 5,
            "y": 4,
            "z": 5,
            "elements": [
                "chisel:glass@9"
            ]
        },
        {
            "x": -5,
            "y": 13,
            "z": 9,
            "elements": [
                "chisel:glass@9"
            ]
        },
        {
            "x": -4,
            "y": 13,
            "z": 9,
            "elements": "pipes_all"
        },
        {
            "x": -3,
            "y": 13,
            "z": 9,
            "elements": "pipes_all"
        },
        {
            "x": -2,
            "y": 13,
            "z": 9,
            "elements": "pipes_all"
        },
        {
            "x": -5,
            "y": 5,
            "z": 5,
            "elements": [
                "chisel:glass@9"
            ]
        },
        {
            "x": -1,
            "y": 13,
            "z": 9,
            "elements": "pipes_all"
        },
        {
            "x": -4,
            "y": 5,
            "z": 5,
            "elements": "pipes_all"
        },
        {
            "x": 0,
            "y": 13,
            "z": 9,
            "elements": "pipes_all"
        },
        {
            "x": -3,
            "y": 5,
            "z": 5,
            "elements": "pipes_all"
        },
        {
            "x": 1,
            "y": 13,
            "z": 9,
            "elements": "pipes_all"
        },
        {
            "x": -2,
            "y": 5,
            "z": 5,
            "elements": "pipes_all"
        },
        {
            "x": 2,
            "y": 13,
            "z": 9,
            "elements": "pipes_all"
        },
        {
            "x": -1,
            "y": 5,
            "z": 5,
            "elements": "pipes_all"
        },
        {
            "x": 3,
            "y": 13,
            "z": 9,
            "elements": "pipes_all"
        },
        {
            "x": 0,
            "y": 5,
            "z": 5,
            "elements": "pipes_all"
        },
        {
            "x": 4,
            "y": 13,
            "z": 9,
            "elements": "pipes_all"
        },
        {
            "x": 1,
            "y": 5,
            "z": 5,
            "elements": "pipes_all"
        },
        {
            "x": 5,
            "y": 13,
            "z": 9,
            "elements": [
                "chisel:glass@9"
            ]
        },
        {
            "x": 2,
            "y": 5,
            "z": 5,
            "elements": "pipes_all"
        },
        {
            "x": 3,
            "y": 5,
            "z": 5,
            "elements": "pipes_all"
        },
        {
            "x": 4,
            "y": 5,
            "z": 5,
            "elements": "pipes_all"
        },
        {
            "x": 5,
            "y": 5,
            "z": 5,
            "elements": [
                "chisel:glass@9"
            ]
        },
        {
            "x": -5,
            "y": 14,
            "z": 9,
            "elements": [
                "chisel:glass@9"
            ]
        },
        {
            "x": -4,
            "y": 14,
            "z": 9,
            "elements": "pipes_all"
        },
        {
            "x": -3,
            "y": 14,
            "z": 9,
            "elements": "pipes_all"
        },
        {
            "x": -2,
            "y": 14,
            "z": 9,
            "elements": "pipes_all"
        },
        {
            "x": -5,
            "y": 6,
            "z": 5,
            "elements": [
                "chisel:glass@9"
            ]
        },
        {
            "x": -1,
            "y": 14,
            "z": 9,
            "elements": "pipes_all"
        },
        {
            "x": -4,
            "y": 6,
            "z": 5,
            "elements": "pipes_all"
        },
        {
            "x": 0,
            "y": 14,
            "z": 9,
            "elements": "pipes_all"
        },
        {
            "x": -3,
            "y": 6,
            "z": 5,
            "elements": "pipes_all"
        },
        {
            "x": 1,
            "y": 14,
            "z": 9,
            "elements": "pipes_all"
        },
        {
            "x": -2,
            "y": 6,
            "z": 5,
            "elements": "pipes_all"
        },
        {
            "x": 2,
            "y": 14,
            "z": 9,
            "elements": "pipes_all"
        },
        {
            "x": -1,
            "y": 6,
            "z": 5,
            "elements": "pipes_all"
        },
        {
            "x": 3,
            "y": 14,
            "z": 9,
            "elements": "pipes_all"
        },
        {
            "x": 0,
            "y": 6,
            "z": 5,
            "elements": "pipes_all"
        },
        {
            "x": 4,
            "y": 14,
            "z": 9,
            "elements": "pipes_all"
        },
        {
            "x": 1,
            "y": 6,
            "z": 5,
            "elements": "pipes_all"
        },
        {
            "x": 5,
            "y": 14,
            "z": 9,
            "elements": [
                "chisel:glass@9"
            ]
        },
        {
            "x": 2,
            "y": 6,
            "z": 5,
            "elements": "pipes_all"
        },
        {
            "x": 3,
            "y": 6,
            "z": 5,
            "elements": "pipes_all"
        },
        {
            "x": 4,
            "y": 6,
            "z": 5,
            "elements": "pipes_all"
        },
        {
            "x": 5,
            "y": 6,
            "z": 5,
            "elements": [
                "chisel:glass@9"
            ]
        },
        {
            "x": -5,
            "y": 15,
            "z": 9,
            "elements": [
                "chisel:glass@9"
            ]
        },
        {
            "x": -4,
            "y": 15,
            "z": 9,
            "elements": "pipes_all"
        },
        {
            "x": -3,
            "y": 15,
            "z": 9,
            "elements": "pipes_all"
        },
        {
            "x": -2,
            "y": 15,
            "z": 9,
            "elements": "pipes_all"
        },
        {
            "x": -5,
            "y": 7,
            "z": 5,
            "elements": [
                "chisel:glass@9"
            ]
        },
        {
            "x": -1,
            "y": 15,
            "z": 9,
            "elements": "pipes_all"
        },
        {
            "x": -4,
            "y": 7,
            "z": 5,
            "elements": "pipes_all"
        },
        {
            "x": 0,
            "y": 15,
            "z": 9,
            "elements": "pipes_all"
        },
        {
            "x": -3,
            "y": 7,
            "z": 5,
            "elements": "pipes_all"
        },
        {
            "x": 1,
            "y": 15,
            "z": 9,
            "elements": "pipes_all"
        },
        {
            "x": -2,
            "y": 7,
            "z": 5,
            "elements": "pipes_all"
        },
        {
            "x": 2,
            "y": 15,
            "z": 9,
            "elements": "pipes_all"
        },
        {
            "x": -1,
            "y": 7,
            "z": 5,
            "elements": "pipes_all"
        },
        {
            "x": 3,
            "y": 15,
            "z": 9,
            "elements": "pipes_all"
        },
        {
            "x": 0,
            "y": 7,
            "z": 5,
            "elements": "pipes_all"
        },
        {
            "x": 4,
            "y": 15,
            "z": 9,
            "elements": "pipes_all"
        },
        {
            "x": 1,
            "y": 7,
            "z": 5,
            "elements": "pipes_all"
        },
        {
            "x": 5,
            "y": 15,
            "z": 9,
            "elements": [
                "chisel:glass@9"
            ]
        },
        {
            "x": 2,
            "y": 7,
            "z": 5,
            "elements": "pipes_all"
        },
        {
            "x": 3,
            "y": 7,
            "z": 5,
            "elements": "pipes_all"
        },
        {
            "x": 4,
            "y": 7,
            "z": 5,
            "elements": "pipes_all"
        },
        {
            "x": 5,
            "y": 7,
            "z": 5,
            "elements": [
                "chisel:glass@9"
            ]
        },
        {
            "x": -5,
            "y": 16,
            "z": 9,
            "elements": [
                "chisel:glass@9"
            ]
        },
        {
            "x": -4,
            "y": 16,
            "z": 9,
            "elements": "pipes_all"
        },
        {
            "x": -3,
            "y": 16,
            "z": 9,
            "elements": "pipes_all"
        },
        {
            "x": -2,
            "y": 16,
            "z": 9,
            "elements": "pipes_all"
        },
        {
            "x": -5,
            "y": 8,
            "z": 5,
            "elements": [
                "chisel:glass@9"
            ]
        },
        {
            "x": -1,
            "y": 16,
            "z": 9,
            "elements": "pipes_all"
        },
        {
            "x": -4,
            "y": 8,
            "z": 5,
            "elements": "pipes_all"
        },
        {
            "x": 0,
            "y": 16,
            "z": 9,
            "elements": "pipes_all"
        },
        {
            "x": -3,
            "y": 8,
            "z": 5,
            "elements": "pipes_all"
        },
        {
            "x": 1,
            "y": 16,
            "z": 9,
            "elements": "pipes_all"
        },
        {
            "x": -2,
            "y": 8,
            "z": 5,
            "elements": "pipes_all"
        },
        {
            "x": 2,
            "y": 16,
            "z": 9,
            "elements": "pipes_all"
        },
        {
            "x": -5,
            "y": 0,
            "z": 1,
            "elements": [
                "contenttweaker:starlight_frame@0"
            ]
        },
        {
            "x": -1,
            "y": 8,
            "z": 5,
            "elements": "pipes_all"
        },
        {
            "x": 3,
            "y": 16,
            "z": 9,
            "elements": "pipes_all"
        },
        {
            "x": -4,
            "y": 0,
            "z": 1,
            "elements": [
                "thaumicaugmentation:fortified_glass@0"
            ]
        },
        {
            "x": 0,
            "y": 8,
            "z": 5,
            "elements": "pipes_all"
        },
        {
            "x": 4,
            "y": 16,
            "z": 9,
            "elements": "pipes_all"
        },
        {
            "x": -3,
            "y": 0,
            "z": 1,
            "elements": [
                "thaumicaugmentation:fortified_glass@0"
            ]
        },
        {
            "x": 1,
            "y": 8,
            "z": 5,
            "elements": "pipes_all"
        },
        {
            "x": 5,
            "y": 16,
            "z": 9,
            "elements": [
                "chisel:glass@9"
            ]
        },
        {
            "x": -2,
            "y": 0,
            "z": 1,
            "elements": [
                "thaumicaugmentation:fortified_glass@0"
            ]
        },
        {
            "x": 2,
            "y": 8,
            "z": 5,
            "elements": "pipes_all"
        },
        {
            "x": -1,
            "y": 0,
            "z": 1,
            "elements": [
                "thaumicaugmentation:fortified_glass@0"
            ]
        },
        {
            "x": 3,
            "y": 8,
            "z": 5,
            "elements": "pipes_all"
        },
        {
            "x": 0,
            "y": 0,
            "z": 1,
            "elements": [
                "thaumicaugmentation:fortified_glass@0"
            ]
        },
        {
            "x": 4,
            "y": 8,
            "z": 5,
            "elements": "pipes_all"
        },
        {
            "x": 1,
            "y": 0,
            "z": 1,
            "elements": [
                "thaumicaugmentation:fortified_glass@0"
            ]
        },
        {
            "x": 5,
            "y": 8,
            "z": 5,
            "elements": [
                "chisel:glass@9"
            ]
        },
        {
            "x": 2,
            "y": 0,
            "z": 1,
            "elements": [
                "thaumicaugmentation:fortified_glass@0"
            ]
        },
        {
            "x": 3,
            "y": 0,
            "z": 1,
            "elements": [
                "thaumicaugmentation:fortified_glass@0"
            ]
        },
        {
            "x": 4,
            "y": 0,
            "z": 1,
            "elements": [
                "thaumicaugmentation:fortified_glass@0"
            ]
        },
        {
            "x": 5,
            "y": 0,
            "z": 1,
            "elements": [
                "contenttweaker:starlight_frame@0"
            ]
        },
        {
            "x": -5,
            "y": 17,
            "z": 9,
            "elements": [
                "chisel:glass@9"
            ]
        },
        {
            "x": -4,
            "y": 17,
            "z": 9,
            "elements": "pipes_all"
        },
        {
            "x": -3,
            "y": 17,
            "z": 9,
            "elements": "pipes_all"
        },
        {
            "x": -2,
            "y": 17,
            "z": 9,
            "elements": "pipes_all"
        },
        {
            "x": -5,
            "y": 9,
            "z": 5,
            "elements": [
                "chisel:glass@9"
            ]
        },
        {
            "x": -1,
            "y": 17,
            "z": 9,
            "elements": "pipes_all"
        },
        {
            "x": -4,
            "y": 9,
            "z": 5,
            "elements": "pipes_all"
        },
        {
            "x": 0,
            "y": 17,
            "z": 9,
            "elements": "pipes_all"
        },
        {
            "x": -3,
            "y": 9,
            "z": 5,
            "elements": "pipes_all"
        },
        {
            "x": 1,
            "y": 17,
            "z": 9,
            "elements": "pipes_all"
        },
        {
            "x": -2,
            "y": 9,
            "z": 5,
            "elements": "pipes_all"
        },
        {
            "x": 2,
            "y": 17,
            "z": 9,
            "elements": "pipes_all"
        },
        {
            "x": -5,
            "y": 1,
            "z": 1,
            "elements": [
                "thaumcraft:stone_arcane@0"
            ]
        },
        {
            "x": -1,
            "y": 9,
            "z": 5,
            "elements": "pipes_all"
        },
        {
            "x": 3,
            "y": 17,
            "z": 9,
            "elements": "pipes_all"
        },
        {
            "x": -4,
            "y": 1,
            "z": 1,
            "elements": [
                "astralsorcery:blockmarble@6"
            ]
        },
        {
            "x": 0,
            "y": 9,
            "z": 5,
            "elements": "pipes_all"
        },
        {
            "x": 4,
            "y": 17,
            "z": 9,
            "elements": "pipes_all"
        },
        {
            "x": -3,
            "y": 1,
            "z": 1,
            "elements": [
                "astralsorcery:blockmarble@4"
            ]
        },
        {
            "x": 1,
            "y": 9,
            "z": 5,
            "elements": "pipes_all"
        },
        {
            "x": 5,
            "y": 17,
            "z": 9,
            "elements": [
                "chisel:glass@9"
            ]
        },
        {
            "x": -2,
            "y": 1,
            "z": 1,
            "elements": [
                "astralsorcery:blockmarble@6"
            ]
        },
        {
            "x": 2,
            "y": 9,
            "z": 5,
            "elements": "pipes_all"
        },
        {
            "x": -1,
            "y": 1,
            "z": 1,
            "elements": [
                "astralsorcery:blockmarble@1"
            ]
        },
        {
            "x": 3,
            "y": 9,
            "z": 5,
            "elements": "pipes_all"
        },
        {
            "x": 0,
            "y": 1,
            "z": 1,
            "elements": [
                "astralsorcery:blockmarble@1"
            ]
        },
        {
            "x": 4,
            "y": 9,
            "z": 5,
            "elements": "pipes_all"
        },
        {
            "x": 1,
            "y": 1,
            "z": 1,
            "elements": [
                "astralsorcery:blockmarble@1"
            ]
        },
        {
            "x": 5,
            "y": 9,
            "z": 5,
            "elements": [
                "chisel:glass@9"
            ]
        },
        {
            "x": 2,
            "y": 1,
            "z": 1,
            "elements": [
                "astralsorcery:blockmarble@3"
            ]
        },
        {
            "x": 3,
            "y": 1,
            "z": 1,
            "elements": [
                "astralsorcery:blockmarble@1"
            ]
        },
        {
